<sdf version='1.6'>
  <model name='pupperv2_description4'>
    <link name='base_link'>
      <pose frame=''>0 0 0 0 -0 0</pose>
      <inertial>
        <pose frame=''>0 -0 4e-06 0 -0 0</pose>
        <mass>0.37691</mass>
        <inertia>
          <ixx>0.00038775</ixx>
          <ixy>1.1873e-06</ixy>
          <ixz>-9.237e-07</ixz>
          <iyy>0.00085802</iyy>
          <iyz>1.7272e-07</iyz>
          <izz>0.0010086</izz>
        </inertia>
      </inertial>
      <collision name='base_link_collision'>
        <pose frame=''>0 0 0 0 -0 0</pose>
        <geometry>
          <mesh>
            <scale>1 1 1</scale>
            <uri>model://pupperv2_description4/meshes/base_link.STL</uri>
          </mesh>
        </geometry>
      </collision>
      <visual name='base_link_visual'>
        <pose frame=''>0 0 0 0 -0 0</pose>
        <geometry>
          <mesh>
            <scale>1 1 1</scale>
            <uri>model://pupperv2_description4/obj_meshes/Cube003.obj</uri>
          </mesh>
        </geometry>
      </visual>
    </link>
    <link name='FL_hip'>
      <pose frame=''>0.029597 0.047 0 0 -0 0</pose>
      <inertial>
        <pose frame=''>0.01877 0.003295 0.00039 0 -0 0</pose>
        <mass>0.032035</mass>
        <inertia>
          <ixx>5.9933e-06</ixx>
          <ixy>4.4808e-07</ixy>
          <ixz>2.4371e-10</ixz>
          <iyy>2.9538e-06</iyy>
          <iyz>6.1996e-08</iyz>
          <izz>5.7278e-06</izz>
        </inertia>
      </inertial>
      <collision name='FL_hip_collision'>
        <pose frame=''>0 0 0 0 -0 0</pose>
        <geometry>
          <mesh>
            <scale>1 1 1</scale>
            <uri>model://pupperv2_description4/meshes/FL_hip.STL</uri>
          </mesh>
        </geometry>
      </collision>
      <visual name='FL_hip_visual'>
        <pose frame=''>0 0 0 0 -0 0</pose>
        <geometry>
          <mesh>
            <scale>1 1 1</scale>
            <uri>model://pupperv2_description4/meshes/FL_hip.STL</uri>
          </mesh>
        </geometry>
      </visual>
    </link>
    <joint name='base_link_FL_hip' type='revolute'>
      <child>FL_hip</child>
      <parent>base_link</parent>
      <axis>
        <xyz>1 0 0</xyz>
        <limit>
          <lower>-0.7854</lower>
          <upper>0.7854</upper>
          <effort>100</effort>
          <velocity>2.5</velocity>
        </limit>
        <dynamics>
          <spring_reference>0</spring_reference>
          <spring_stiffness>0</spring_stiffness>
        </dynamics>
        <use_parent_model_frame>1</use_parent_model_frame>
      </axis>
    </joint>
    <link name='FL_upper_leg'>
      <pose frame=''>0.044847 0.07235 0 0 -0 0</pose>
      <inertial>
        <pose frame=''>0.000116 0.025203 -0.048064 0 -0 0</pose>
        <mass>0.054665</mass>
        <inertia>
          <ixx>2.4386e-05</ixx>
          <ixy>1.682e-10</ixy>
          <ixz>2.6061e-07</ixz>
          <iyy>2.3437e-05</iyy>
          <iyz>2.7137e-07</iyz>
          <izz>6.6679e-06</izz>
        </inertia>
      </inertial>
      <collision name='FL_upper_leg_collision'>
        <pose frame=''>0 0 0 0 -0 0</pose>
        <geometry>
          <mesh>
            <scale>1 1 1</scale>
            <uri>model://pupperv2_description4/meshes/FL_upper_leg.STL</uri>
          </mesh>
        </geometry>
      </collision>
      <visual name='FL_upper_leg_visual'>
        <pose frame=''>0 0 0 0 -0 0</pose>
        <geometry>
          <mesh>
            <scale>1 1 1</scale>
            <uri>model://pupperv2_description4/meshes/FL_upper_leg.STL</uri>
          </mesh>
        </geometry>
      </visual>
    </link>
    <joint name='FL_hip_FL_upper_leg' type='revolute'>
      <child>FL_upper_leg</child>
      <parent>FL_hip</parent>
      <axis>
        <xyz>0 1 0</xyz>
        <limit>
          <lower>-1.309</lower>
          <upper>4.4506</upper>
          <effort>100</effort>
          <velocity>2.5</velocity>
        </limit>
        <dynamics>
          <spring_reference>0</spring_reference>
          <spring_stiffness>0</spring_stiffness>
        </dynamics>
        <use_parent_model_frame>1</use_parent_model_frame>
      </axis>
    </joint>
    <link name='FL_lower_leg'>
      <pose frame=''>0.044847 0.07235 -0.08 0 -0 0</pose>
      <inertial>
        <pose frame=''>2.9e-05 0.004388 -0.047513 0 -0 0</pose>
        <mass>0.0185279</mass>
        <inertia>
          <ixx>2.69352e-05</ixx>
          <ixy>-1.47429e-09</ixy>
          <ixz>-5.82501e-08</ixz>
          <iyy>2.71324e-05</iyy>
          <iyz>1.19137e-06</iyz>
          <izz>6.50898e-07</izz>
        </inertia>
      </inertial>
      <collision name='FL_lower_leg_collision'>
        <pose frame=''>0 0 0 0 -0 0</pose>
        <geometry>
          <mesh>
            <scale>1 1 1</scale>
            <uri>model://pupperv2_description4/meshes/FL_lower_leg.STL</uri>
          </mesh>
        </geometry>
      </collision>
      <collision name='FL_lower_leg_fixed_joint_lump__FL_toe_collision_1'>
        <pose frame=''>0 0.008325 -0.11 0 -0 0</pose>
        <geometry>
          <mesh>
            <scale>1 1 1</scale>
            <uri>model://pupperv2_description4/meshes/FL_toe.STL</uri>
          </mesh>
        </geometry>
        <surface>
          <contact>
            <ode>
              <kp>1e+06</kp>
              <kd>1</kd>
              <max_vel>0</max_vel>
              <min_depth>0.001</min_depth>
            </ode>
          </contact>
          <friction>
            <ode>
              <mu>0.8</mu>
              <mu2>0.8</mu2>
            </ode>
          </friction>
        </surface>
      </collision>
      <visual name='FL_lower_leg_visual'>
        <pose frame=''>0 0 0 0 -0 0</pose>
        <geometry>
          <mesh>
            <scale>1 1 1</scale>
            <uri>model://pupperv2_description4/meshes/FL_lower_leg.STL</uri>
          </mesh>
        </geometry>
      </visual>
      <visual name='FL_lower_leg_fixed_joint_lump__FL_toe_visual_1'>
        <pose frame=''>0 0.008325 -0.11 0 -0 0</pose>
        <geometry>
          <mesh>
            <scale>1 1 1</scale>
            <uri>model://pupperv2_description4/meshes/FL_toe.STL</uri>
          </mesh>
        </geometry>
        <material>
          <script>
            <uri>__default__</uri>
            <name>__default__</name>
          </script>
        </material>
      </visual>
      <gravity>1</gravity>
      <velocity_decay/>
    </link>
    <joint name='FL_upper_leg_FL_lower_leg' type='revolute'>
      <child>FL_lower_leg</child>
      <parent>FL_upper_leg</parent>
      <axis>
        <xyz>0 1 0</xyz>
        <limit>
          <lower>-2.8798</lower>
          <upper>2.8798</upper>
          <effort>100</effort>
          <velocity>2.5</velocity>
        </limit>
        <dynamics>
          <spring_reference>0</spring_reference>
          <spring_stiffness>0</spring_stiffness>
        </dynamics>
        <use_parent_model_frame>1</use_parent_model_frame>
      </axis>
    </joint>
    <link name='FR_hip'>
      <pose frame=''>0.029475 -0.047 0 0 -0 0</pose>
      <inertial>
        <pose frame=''>0.018798 -0.003274 0.000397 0 -0 0</pose>
        <mass>0.032069</mass>
        <inertia>
          <ixx>5.9912e-06</ixx>
          <ixy>-4.4714e-07</ixy>
          <ixz>1.8534e-10</ixz>
          <iyy>2.954e-06</iyy>
          <iyz>-6.2909e-08</iyz>
          <izz>5.7295e-06</izz>
        </inertia>
      </inertial>
      <collision name='FR_hip_collision'>
        <pose frame=''>0 0 0 0 -0 0</pose>
        <geometry>
          <mesh>
            <scale>1 1 1</scale>
            <uri>model://pupperv2_description4/meshes/FR_hip.STL</uri>
          </mesh>
        </geometry>
      </collision>
      <visual name='FR_hip_visual'>
        <pose frame=''>0 0 0 0 -0 0</pose>
        <geometry>
          <mesh>
            <scale>1 1 1</scale>
            <uri>model://pupperv2_description4/meshes/FR_hip.STL</uri>
          </mesh>
        </geometry>
      </visual>
    </link>
    <joint name='base_link_FR_hip' type='revolute'>
      <child>FR_hip</child>
      <parent>base_link</parent>
      <axis>
        <xyz>1 0 0</xyz>
        <limit>
          <lower>-0.7854</lower>
          <upper>0.7854</upper>
          <effort>100</effort>
          <velocity>2.5</velocity>
        </limit>
        <dynamics>
          <spring_reference>0</spring_reference>
          <spring_stiffness>0</spring_stiffness>
        </dynamics>
        <use_parent_model_frame>1</use_parent_model_frame>
      </axis>
    </joint>
    <link name='FR_upper_leg'>
      <pose frame=''>0.044727 -0.07235 0 0 -0 0</pose>
      <inertial>
        <pose frame=''>-0.000116 -0.025203 -0.048064 0 -0 0</pose>
        <mass>0.054665</mass>
        <inertia>
          <ixx>2.4386e-05</ixx>
          <ixy>1.682e-10</ixy>
          <ixz>-2.6061e-07</ixz>
          <iyy>2.3437e-05</iyy>
          <iyz>-2.7137e-07</iyz>
          <izz>6.6679e-06</izz>
        </inertia>
      </inertial>
      <collision name='FR_upper_leg_collision'>
        <pose frame=''>0 0 0 0 -0 0</pose>
        <geometry>
          <mesh>
            <scale>1 1 1</scale>
            <uri>model://pupperv2_description4/meshes/FR_upper_leg.STL</uri>
          </mesh>
        </geometry>
      </collision>
      <visual name='FR_upper_leg_visual'>
        <pose frame=''>0 0 0 0 -0 0</pose>
        <geometry>
          <mesh>
            <scale>1 1 1</scale>
            <uri>model://pupperv2_description4/meshes/FR_upper_leg.STL</uri>
          </mesh>
        </geometry>
      </visual>
    </link>
    <joint name='FR_hip_FR_upper_leg' type='revolute'>
      <child>FR_upper_leg</child>
      <parent>FR_hip</parent>
      <axis>
        <xyz>0 1 0</xyz>
        <limit>
          <lower>-4.4506</lower>
          <upper>1.309</upper>
          <effort>100</effort>
          <velocity>2.5</velocity>
        </limit>
        <dynamics>
          <spring_reference>0</spring_reference>
          <spring_stiffness>0</spring_stiffness>
        </dynamics>
        <use_parent_model_frame>1</use_parent_model_frame>
      </axis>
    </joint>
    <link name='FR_lower_leg'>
      <pose frame=''>0.044727 -0.07235 -0.08 0 -0 0</pose>
      <inertial>
        <pose frame=''>3.2e-05 -0.004401 -0.047451 0 -0 0</pose>
        <mass>0.0185509</mass>
        <inertia>
          <ixx>2.6944e-05</ixx>
          <ixy>1.53789e-09</ixy>
          <ixz>-5.9142e-08</ixz>
          <iyy>2.71415e-05</iyy>
          <iyz>-1.19065e-06</iyz>
          <izz>6.51218e-07</izz>
        </inertia>
      </inertial>
      <collision name='FR_lower_leg_collision'>
        <pose frame=''>0 0 0 0 -0 0</pose>
        <geometry>
          <mesh>
            <scale>1 1 1</scale>
            <uri>model://pupperv2_description4/meshes/FR_lower_leg.STL</uri>
          </mesh>
        </geometry>
      </collision>
      <collision name='FR_lower_leg_fixed_joint_lump__FR_toe_collision_1'>
        <pose frame=''>0 -0.008325 -0.11 0 -0 0</pose>
        <geometry>
          <mesh>
            <scale>1 1 1</scale>
            <uri>model://pupperv2_description4/meshes/FR_toe.STL</uri>
          </mesh>
        </geometry>
        <surface>
          <contact>
            <ode>
              <kp>1e+06</kp>
              <kd>1</kd>
              <max_vel>0</max_vel>
              <min_depth>0.001</min_depth>
            </ode>
          </contact>
          <friction>
            <ode>
              <mu>0.8</mu>
              <mu2>0.8</mu2>
            </ode>
          </friction>
        </surface>
      </collision>
      <visual name='FR_lower_leg_visual'>
        <pose frame=''>0 0 0 0 -0 0</pose>
        <geometry>
          <mesh>
            <scale>1 1 1</scale>
            <uri>model://pupperv2_description4/meshes/FR_lower_leg.STL</uri>
          </mesh>
        </geometry>
      </visual>
      <visual name='FR_lower_leg_fixed_joint_lump__FR_toe_visual_1'>
        <pose frame=''>0 -0.008325 -0.11 0 -0 0</pose>
        <geometry>
          <mesh>
            <scale>1 1 1</scale>
            <uri>model://pupperv2_description4/meshes/FR_toe.STL</uri>
          </mesh>
        </geometry>
        <material>
          <script>
            <uri>__default__</uri>
            <name>__default__</name>
          </script>
        </material>
      </visual>
      <gravity>1</gravity>
      <velocity_decay/>
    </link>
    <joint name='FR_upper_leg_FR_lower_leg' type='revolute'>
      <child>FR_lower_leg</child>
      <parent>FR_upper_leg</parent>
      <axis>
        <xyz>0 1 0</xyz>
        <limit>
          <lower>-2.8798</lower>
          <upper>2.8798</upper>
          <effort>100</effort>
          <velocity>2.5</velocity>
        </limit>
        <dynamics>
          <spring_reference>0</spring_reference>
          <spring_stiffness>0</spring_stiffness>
        </dynamics>
        <use_parent_model_frame>1</use_parent_model_frame>
      </axis>
    </joint>
    <link name='RL_hip'>
      <pose frame=''>-0.12913 0.047 0 0 -0 0</pose>
      <inertial>
        <pose frame=''>-0.022505 0.003295 0.00039 0 -0 0</pose>
        <mass>0.032035</mass>
        <inertia>
          <ixx>5.9933e-06</ixx>
          <ixy>4.4808e-07</ixy>
          <ixz>2.4371e-10</ixz>
          <iyy>2.9538e-06</iyy>
          <iyz>6.1996e-08</iyz>
          <izz>5.7278e-06</izz>
        </inertia>
      </inertial>
      <collision name='RL_hip_collision'>
        <pose frame=''>0 0 0 0 -0 0</pose>
        <geometry>
          <mesh>
            <scale>1 1 1</scale>
            <uri>model://pupperv2_description4/meshes/RL_hip.STL</uri>
          </mesh>
        </geometry>
      </collision>
      <visual name='RL_hip_visual'>
        <pose frame=''>0 0 0 0 -0 0</pose>
        <geometry>
          <mesh>
            <scale>1 1 1</scale>
            <uri>model://pupperv2_description4/meshes/RL_hip.STL</uri>
          </mesh>
        </geometry>
      </visual>
    </link>
    <joint name='base_link_RL_hip' type='revolute'>
      <child>RL_hip</child>
      <parent>base_link</parent>
      <axis>
        <xyz>1 0 0</xyz>
        <limit>
          <lower>-0.7854</lower>
          <upper>0.7854</upper>
          <effort>100</effort>
          <velocity>2.5</velocity>
        </limit>
        <dynamics>
          <spring_reference>0</spring_reference>
          <spring_stiffness>0</spring_stiffness>
        </dynamics>
        <use_parent_model_frame>1</use_parent_model_frame>
      </axis>
    </joint>
    <link name='RL_upper_leg'>
      <pose frame=''>-0.155155 0.07235 0 0 0.001131 0</pose>
      <inertial>
        <pose frame=''>0.000116 0.025203 -0.048064 0 -0 0</pose>
        <mass>0.054665</mass>
        <inertia>
          <ixx>2.4386e-05</ixx>
          <ixy>1.682e-10</ixy>
          <ixz>2.6061e-07</ixz>
          <iyy>2.3437e-05</iyy>
          <iyz>2.7137e-07</iyz>
          <izz>6.6679e-06</izz>
        </inertia>
      </inertial>
      <collision name='RL_upper_leg_collision'>
        <pose frame=''>0 0 0 0 -0 0</pose>
        <geometry>
          <mesh>
            <scale>1 1 1</scale>
            <uri>model://pupperv2_description4/meshes/RL_upper_leg.STL</uri>
          </mesh>
        </geometry>
      </collision>
      <visual name='RL_upper_leg_visual'>
        <pose frame=''>0 0 0 0 -0 0</pose>
        <geometry>
          <mesh>
            <scale>1 1 1</scale>
            <uri>model://pupperv2_description4/meshes/RL_upper_leg.STL</uri>
          </mesh>
        </geometry>
      </visual>
    </link>
    <joint name='RL_hip_RL_upper_leg' type='revolute'>
      <child>RL_upper_leg</child>
      <parent>RL_hip</parent>
      <axis>
        <xyz>0 1 0</xyz>
        <limit>
          <lower>-1.309</lower>
          <upper>4.4506</upper>
          <effort>100</effort>
          <velocity>2.5</velocity>
        </limit>
        <dynamics>
          <spring_reference>0</spring_reference>
          <spring_stiffness>0</spring_stiffness>
        </dynamics>
        <use_parent_model_frame>1</use_parent_model_frame>
      </axis>
    </joint>
    <link name='RL_lower_leg'>
      <pose frame=''>-0.155245 0.07235 -0.08 0 -0 0</pose>
      <inertial>
        <pose frame=''>2.9e-05 0.004388 -0.047513 0 -0 0</pose>
        <mass>0.0185279</mass>
        <inertia>
          <ixx>2.69352e-05</ixx>
          <ixy>-1.47429e-09</ixy>
          <ixz>-5.82501e-08</ixz>
          <iyy>2.71324e-05</iyy>
          <iyz>1.19137e-06</iyz>
          <izz>6.50898e-07</izz>
        </inertia>
      </inertial>
      <collision name='RL_lower_leg_collision'>
        <pose frame=''>0 0 0 0 -0 0</pose>
        <geometry>
          <mesh>
            <scale>1 1 1</scale>
            <uri>model://pupperv2_description4/meshes/RL_lower_leg.STL</uri>
          </mesh>
        </geometry>
      </collision>
      <collision name='RL_lower_leg_fixed_joint_lump__RL_toe_collision_1'>
        <pose frame=''>0 0.008325 -0.11 0 -0 0</pose>
        <geometry>
          <mesh>
            <scale>1 1 1</scale>
            <uri>model://pupperv2_description4/meshes/RL_toe.STL</uri>
          </mesh>
        </geometry>
        <surface>
          <contact>
            <ode>
              <kp>1e+06</kp>
              <kd>1</kd>
              <max_vel>0</max_vel>
              <min_depth>0.001</min_depth>
            </ode>
          </contact>
          <friction>
            <ode>
              <mu>0.8</mu>
              <mu2>0.8</mu2>
            </ode>
          </friction>
        </surface>
      </collision>
      <visual name='RL_lower_leg_visual'>
        <pose frame=''>0 0 0 0 -0 0</pose>
        <geometry>
          <mesh>
            <scale>1 1 1</scale>
            <uri>model://pupperv2_description4/meshes/RL_lower_leg.STL</uri>
          </mesh>
        </geometry>
      </visual>
      <visual name='RL_lower_leg_fixed_joint_lump__RL_toe_visual_1'>
        <pose frame=''>0 0.008325 -0.11 0 -0 0</pose>
        <geometry>
          <mesh>
            <scale>1 1 1</scale>
            <uri>model://pupperv2_description4/meshes/RL_toe.STL</uri>
          </mesh>
        </geometry>
        <material>
          <script>
            <uri>__default__</uri>
            <name>__default__</name>
          </script>
        </material>
      </visual>
      <gravity>1</gravity>
      <velocity_decay/>
    </link>
    <joint name='RL_upper_leg_RL_lower_leg' type='revolute'>
      <child>RL_lower_leg</child>
      <parent>RL_upper_leg</parent>
      <axis>
        <xyz>0 1 0</xyz>
        <limit>
          <lower>-2.8798</lower>
          <upper>2.8798</upper>
          <effort>100</effort>
          <velocity>2.5</velocity>
        </limit>
        <dynamics>
          <spring_reference>0</spring_reference>
          <spring_stiffness>0</spring_stiffness>
        </dynamics>
        <use_parent_model_frame>1</use_parent_model_frame>
      </axis>
    </joint>
    <link name='RR_hip'>
      <pose frame=''>-0.12925 -0.047 0 0 -0 0</pose>
      <inertial>
        <pose frame=''>-0.022479 -0.003274 0.000397 0 -0 0</pose>
        <mass>0.032069</mass>
        <inertia>
          <ixx>5.9912e-06</ixx>
          <ixy>-4.4714e-07</ixy>
          <ixz>1.8534e-10</ixz>
          <iyy>2.954e-06</iyy>
          <iyz>-6.2909e-08</iyz>
          <izz>5.7295e-06</izz>
        </inertia>
      </inertial>
      <collision name='RR_hip_collision'>
        <pose frame=''>0 0 0 0 -0 0</pose>
        <geometry>
          <mesh>
            <scale>1 1 1</scale>
            <uri>model://pupperv2_description4/meshes/RR_hip.STL</uri>
          </mesh>
        </geometry>
      </collision>
      <visual name='RR_hip_visual'>
        <pose frame=''>0 0 0 0 -0 0</pose>
        <geometry>
          <mesh>
            <scale>1 1 1</scale>
            <uri>model://pupperv2_description4/meshes/RR_hip.STL</uri>
          </mesh>
        </geometry>
      </visual>
    </link>
    <joint name='base_link_RR_hip' type='revolute'>
      <child>RR_hip</child>
      <parent>base_link</parent>
      <axis>
        <xyz>1 0 0</xyz>
        <limit>
          <lower>-0.7854</lower>
          <upper>0.7854</upper>
          <effort>100</effort>
          <velocity>2.5</velocity>
        </limit>
        <dynamics>
          <spring_reference>0</spring_reference>
          <spring_stiffness>0</spring_stiffness>
        </dynamics>
        <use_parent_model_frame>1</use_parent_model_frame>
      </axis>
    </joint>
    <link name='RR_upper_leg'>
      <pose frame=''>-0.155275 -0.07235 0 0 -0 0</pose>
      <inertial>
        <pose frame=''>-0.000116 -0.025203 -0.048064 0 -0 0</pose>
        <mass>0.054665</mass>
        <inertia>
          <ixx>2.4386e-05</ixx>
          <ixy>1.682e-10</ixy>
          <ixz>-2.6061e-07</ixz>
          <iyy>2.3437e-05</iyy>
          <iyz>-2.7137e-07</iyz>
          <izz>6.6679e-06</izz>
        </inertia>
      </inertial>
      <collision name='RR_upper_leg_collision'>
        <pose frame=''>0 0 0 0 -0 0</pose>
        <geometry>
          <mesh>
            <scale>1 1 1</scale>
            <uri>model://pupperv2_description4/meshes/RR_upper_leg.STL</uri>
          </mesh>
        </geometry>
      </collision>
      <visual name='RR_upper_leg_visual'>
        <pose frame=''>0 0 0 0 -0 0</pose>
        <geometry>
          <mesh>
            <scale>1 1 1</scale>
            <uri>model://pupperv2_description4/meshes/RR_upper_leg.STL</uri>
          </mesh>
        </geometry>
      </visual>
    </link>
    <joint name='RR_hip_RR_upper_leg' type='revolute'>
      <child>RR_upper_leg</child>
      <parent>RR_hip</parent>
      <axis>
        <xyz>0 1 0</xyz>
        <limit>
          <lower>-4.4506</lower>
          <upper>1.309</upper>
          <effort>100</effort>
          <velocity>2.5</velocity>
        </limit>
        <dynamics>
          <spring_reference>0</spring_reference>
          <spring_stiffness>0</spring_stiffness>
        </dynamics>
        <use_parent_model_frame>1</use_parent_model_frame>
      </axis>
    </joint>
    <link name='RR_lower_leg'>
      <pose frame=''>-0.155275 -0.07235 -0.08 0 -0 0</pose>
      <inertial>
        <pose frame=''>3.2e-05 -0.004401 -0.047451 0 -0 0</pose>
        <mass>0.0185509</mass>
        <inertia>
          <ixx>2.6944e-05</ixx>
          <ixy>1.53789e-09</ixy>
          <ixz>-5.9142e-08</ixz>
          <iyy>2.71415e-05</iyy>
          <iyz>-1.19065e-06</iyz>
          <izz>6.51218e-07</izz>
        </inertia>
      </inertial>
      <collision name='RR_lower_leg_collision'>
        <pose frame=''>0 0 0 0 -0 0</pose>
        <geometry>
          <mesh>
            <scale>1 1 1</scale>
            <uri>model://pupperv2_description4/meshes/RR_lower_leg.STL</uri>
          </mesh>
        </geometry>
      </collision>
      <collision name='RR_lower_leg_fixed_joint_lump__RR_toe_collision_1'>
        <pose frame=''>0 -0.008325 -0.11 0 -0 0</pose>
        <geometry>
          <mesh>
            <scale>1 1 1</scale>
            <uri>model://pupperv2_description4/meshes/RR_toe.STL</uri>
          </mesh>
        </geometry>
        <surface>
          <contact>
            <ode>
              <kp>1e+06</kp>
              <kd>1</kd>
              <max_vel>0</max_vel>
              <min_depth>0.001</min_depth>
            </ode>
          </contact>
          <friction>
            <ode>
              <mu>0.8</mu>
              <mu2>0.8</mu2>
            </ode>
          </friction>
        </surface>
      </collision>
      <visual name='RR_lower_leg_visual'>
        <pose frame=''>0 0 0 0 -0 0</pose>
        <geometry>
          <mesh>
            <scale>1 1 1</scale>
            <uri>model://pupperv2_description4/meshes/RR_lower_leg.STL</uri>
          </mesh>
        </geometry>
      </visual>
      <visual name='RR_lower_leg_fixed_joint_lump__RR_toe_visual_1'>
        <pose frame=''>0 -0.008325 -0.11 0 -0 0</pose>
        <geometry>
          <mesh>
            <scale>1 1 1</scale>
            <uri>model://pupperv2_description4/meshes/RR_toe.STL</uri>
          </mesh>
        </geometry>
        <material>
          <script>
            <uri>__default__</uri>
            <name>__default__</name>
          </script>
        </material>
      </visual>
      <gravity>1</gravity>
      <velocity_decay/>
    </link>
    <joint name='RR_upper_leg_RR_lower_leg' type='revolute'>
      <child>RR_lower_leg</child>
      <parent>RR_upper_leg</parent>
      <axis>
        <xyz>0 1 0</xyz>
        <limit>
          <lower>-2.8798</lower>
          <upper>2.8798</upper>
          <effort>100</effort>
          <velocity>2.5</velocity>
        </limit>
        <dynamics>
          <spring_reference>0</spring_reference>
          <spring_stiffness>0</spring_stiffness>
        </dynamics>
        <use_parent_model_frame>1</use_parent_model_frame>
      </axis>
    </joint>
    <static>0</static>
    <plugin name='gazebo_ros_control' filename='libgazebo_ros_control.so'>
      <legacyModeNS>1</legacyModeNS>
      <robotSimType>gazebo_ros_control/DefaultRobotHWSim</robotSimType>
    </plugin>
  </model>
</sdf>
